Workbook

Sheet Assumptions
A1: LAAA UNDERWRITING BENCHMARKS (edit here; every deal tab reads these)
A3: Vacancy & credit loss (% of GSI) | B3: 0.03 | C3: Standard LA practice; vacant units carried at asking rent inside scheduled GSR
A4: Management fee (% of EGI) | B4: 0.05 | C4: Deal-by-deal agent choice; 5% default, MAX(OM, benchmark) used
A5: Insurance: per unit ($) | B5: 200 | C5: LAAA benchmark = (units x $200) + (gross SF x $1.00)
A6: Insurance: per gross SF ($) | B6: 1
A7: Repairs & maintenance per unit, pre-1990 ($/yr) | B7: 1200
A8: Repairs & maintenance per unit, 1990+ ($/yr) | B8: 800
A9: Utilities per unit, LA City ($/yr) | B9: 1500 | C9: Owner-paid water/sewer/trash/common electric+gas (LA Sanitation bundles trash)
A10: Utilities per unit, Santa Monica ($/yr) | B10: 1800 | C10: Separate trash hauler, higher water rates
A11: Utilities per unit, Beverly Hills / WeHo / Culver ($/yr) | B11: 1600
A12: Contract services per unit ($/yr) | B12: 400 | C12: Landscaping, pest, common-area cleaning
A13: Admin / legal / licenses / rent registration per unit ($/yr) | B13: 250 | C13: Includes RSO/rent-board fees, business license, bookkeeping
A14: Replacement reserves per unit ($/yr) | B14: 300
A15: Property tax rate: Los Angeles City | B15: 0.0125 | C15: Ad valorem + direct assessments, reassessed at purchase price
A16: Property tax rate: Santa Monica | B16: 0.0115
A17: Property tax rate: Beverly Hills | B17: 0.0115
A18: Property tax rate: West Hollywood | B18: 0.012
A19: Property tax rate: Culver City | B19: 0.012
A20: Financing: max LTV | B20: 0.6
A21: Financing: min DCR on LAAA NOI | B21: 1.25 | C21: Loan = lesser of LTV loan and DCR-sized loan
A22: Financing: interest rate | B22: 0.0625
A23: Financing: amortization (years) | B23: 30
A24: OM "light" threshold: LAAA total exceeds OM total by more than | B24: 0.05 | C24: Flags OM EXPENSES LIGHT on the deal tab and Master List
A26: Rent-allocation weights when only GRM is published (relative to 1 Bd)
A27: Studio | B27: 0.7
A28: 1 Bd | B28: 1
A29: 2 Bd | B29: 1.35
A30: 3 Bd | B30: 1.75
A32: Estimated in-place rents when NOTHING is published (orange cells on deal tabs)
A33: Coastal (SM / Venice / WeHo / BH): Studio | B33: 1900
A34: Coastal: 1 Bd | B34: 2400
A35: Coastal: 2 Bd | B35: 3200
A36: Coastal: 3 Bd | B36: 4200
A37: West LA / Palms / Culver: Studio | B37: 1750
A38: West LA / Palms / Culver: 1 Bd | B38: 2200
A39: West LA / Palms / Culver: 2 Bd | B39: 2900
A40: West LA / Palms / Culver: 3 Bd | B40: 3800

Sheet 02 1129 Lincoln Blvd
A1: 1129 Lincoln Blvd
A2: Santa Monica, CA 90403 | Santa Monica
A3: LoopNet listing | B3: Data pulled 9/17/2026 from LoopNet public listing
A6: PROPERTY
A7: Units | B7: 10
A8: Gross building SF | B8: 7377
A9: Lot SF | B9: 7405
A10: Lot acres | B10: 0.17
A11: Year built | B11: 1956
A12: Stories | B12: 1
A13: Zoning | B13: SMR3AY - Santa Monica R2 - Multi-Residential
A14: Occupancy per listing | B14: 100%
A15: APN | B15: 4281-035-016
A16: Assessed value (current) | B16: 787301
A17: Listing broker(s) | B17: Stephen Lampe
A18: Date on market | B18: 3/9/2026
A19: Listing last updated | B19: 8/18/2026
A21: PRICING
A22: Asking price | B22: 3100000
A23: Price per unit | B23: =IFERROR(B22/B7,"") -> 310000
A24: Price per gross SF | B24: =IFERROR(B22/B8,"") -> 420.22502
A25: OM / listing cap rate (as published) | B25: 0.0632
A26: OM / listing GRM (as published) | B26: 11.16
A28: UNIT MIX & SCHEDULED RENT
A29: Unit type | B29: # Units | C29: Avg rent / mo | D29: Monthly total | E29: Annual | F29: Rent source
A30: 2 Bd / 2 Ba | B30: 1 | C30: 2296 | D30: =B30*C30 -> 2296 | E30: =D30*12 -> 27552 | F30: LoopNet published avg rent by unit type
A31: 2 Bd / 1.5 Ba | B31: 1 | C31: 2840 | D31: =B31*C31 -> 2840 | E31: =D31*12 -> 34080 | F31: LoopNet published avg rent by unit type
A32: 2 Bd / 1 Ba | B32: 1 | C32: 2995 | D32: =B32*C32 -> 2995 | E32: =D32*12 -> 35940 | F32: LoopNet published avg rent by unit type
A33: 1 Bd / 1 Ba | B33: 5 | C33: 2300 | D33: =B33*C33 -> 11500 | E33: =D33*12 -> 138000 | F33: LoopNet published avg rent by unit type
A34: Studio | B34: 2 | C34: 1922 | D34: =B34*C34 -> 3844 | E34: =D34*12 -> 46128 | F34: LoopNet published avg rent by unit type
A35: Total / weighted avg | B35: =SUM(B30:B34) -> 10 | C35: =IFERROR(D35/B35,"") -> 2347.5 | D35: =SUM(D30:D34) -> 23475 | E35: =SUM(E30:E34) -> 281700
A37: INCOME
B38: OM as presented | C38: LAAA underwritten | F38: Basis / note
A39: Scheduled gross rent | B39: 277777.78 | C39: =E35 -> 281700 | F39: OM column: price / published GRM
A40: Other income (laundry, parking, RUBS) | B40: 0 | C40: 0
A41: Gross scheduled income | B41: =B39+B40 -> 277777.78 | C41: =C39+C40 -> 281700
A42: Vacancy & credit loss | B42: =-B39*0.03 -> -8333.3333 | C42: =-C39*Assumptions!$B$3 -> -8451 | F42: OM 3.0% (OM figure if extracted, else 3% assumed); LAAA per Assumptions
A43: Effective gross income | B43: =B41+B42 -> 269444.44 | C43: =C41+C42 -> 273249
A45: OPERATING EXPENSES
A46: Expense line | B46: OM as presented | C46: LAAA benchmark | D46: LAAA underwritten | E46: Delta vs OM | F46: Basis / note
...
