Workbook

Sheet Assumptions
A1: LAAA UNDERWRITING BENCHMARKS (edit here; every deal tab reads these)
A3: Vacancy & credit loss (% of GSI) | B3: 0.03 | C3: Standard LA practice; vacant units carried at asking rent inside scheduled GSR
A4: Management fee (% of EGI) | B4: 0.05 | C4: Deal-by-deal agent choice; 5% default, MAX(OM, benchmark) used
A5: Insurance: per unit ($) | B5: 200 | C5: LAAA benchmark = (units x $200) + (gross SF x $1.00)
A6: Insurance: per gross SF ($) | B6: 1
A7: Repairs & maintenance per unit, pre-1990 ($/yr) | B7: 1200
A8: Repairs & maintenance per unit, 1990+ ($/yr) | B8: 800
A9: Utilities per unit, LA City ($/yr) | B9: 1500 | C9: Owner-paid water/sewer/trash/common electric+gas (LA Sanitation bundles trash)
A10: Utilities per unit, Santa Monica ($/yr) | B10: 1800 | C10: Separate trash hauler, higher water rates
A11: Utilities per unit, Beverly Hills / WeHo / Culver ($/yr) | B11: 1600
A12: Contract services per unit ($/yr) | B12: 400 | C12: Landscaping, pest, common-area cleaning
A13: Admin / legal / licenses / rent registration per unit ($/yr) | B13: 250 | C13: Includes RSO/rent-board fees, business license, bookkeeping
A14: Replacement reserves per unit ($/yr) | B14: 300
A15: Property tax rate: Los Angeles City | B15: 0.0125 | C15: Ad valorem + direct assessments, reassessed at purchase price
A16: Property tax rate: Santa Monica | B16: 0.0115
A17: Property tax rate: Beverly Hills | B17: 0.0115
A18: Property tax rate: West Hollywood | B18: 0.012
A19: Property tax rate: Culver City | B19: 0.012
A20: Financing: max LTV | B20: 0.6
A21: Financing: min DCR on LAAA NOI | B21: 1.25 | C21: Loan = lesser of LTV loan and DCR-sized loan
A22: Financing: interest rate | B22: 0.0625
A23: Financing: amortization (years) | B23: 30
A24: OM "light" threshold: LAAA total exceeds OM total by more than | B24: 0.05 | C24: Flags OM EXPENSES LIGHT on the deal tab and Master List
A26: Rent-allocation weights when only GRM is published (relative to 1 Bd)
A27: Studio | B27: 0.7
A28: 1 Bd | B28: 1
A29: 2 Bd | B29: 1.35
A30: 3 Bd | B30: 1.75
A32: Estimated in-place rents when NOTHING is published (orange cells on deal tabs)
A33: Coastal (SM / Venice / WeHo / BH): Studio | B33: 1900
A34: Coastal: 1 Bd | B34: 2400
A35: Coastal: 2 Bd | B35: 3200
A36: Coastal: 3 Bd | B36: 4200
A37: West LA / Palms / Culver: Studio | B37: 1750
A38: West LA / Palms / Culver: 1 Bd | B38: 2200
A39: West LA / Palms / Culver: 2 Bd | B39: 2900
A40: West LA / Palms / Culver: 3 Bd | B40: 3800

Sheet 07 2626 Cloverfield Blvd
A1: 2626 Cloverfield Blvd
A2: Santa Monica, CA 90405 | Santa Monica
A3: LoopNet listing | B3: Data pulled 9/17/2026 from LoopNet public listing
A6: PROPERTY
A7: Units | B7: 12
A8: Gross building SF | B8: 7280
A9: Lot SF | B9: 6098
A10: Lot acres | B10: 0.14
A11: Year built
A12: Stories | B12: 2
A13: Zoning | B13: SMR3* - residential
A14: Occupancy per listing
A15: APN | B15: 4273-012-016
A16: Assessed value (current) | B16: 4590000
A17: Listing broker(s) | B17: Steve Bogoyevac, David O'Keefe
A18: Date on market | B18: 4/8/2026
A19: Listing last updated | B19: 9/8/2026
A21: PRICING
A22: Asking price | B22: 4750000
A23: Price per unit | B23: =IFERROR(B22/B7,"") -> 395833.33
A24: Price per gross SF | B24: =IFERROR(B22/B8,"") -> 652.47253
A25: OM / listing cap rate (as published) | B25: 0.0559
A26: OM / listing GRM (as published) | B26: 12.76
A28: UNIT MIX & SCHEDULED RENT
A29: Unit type | B29: # Units | C29: Avg rent / mo | D29: Monthly total | E29: Annual | F29: Rent source
A30: Studio (~450 SF) | B30: 1 | C30: 1856 | D30: =B30*C30 -> 1856 | E30: =D30*12 -> 22272 | F30: Allocated from published GRM (price / GRM) using LAAA bed weights
A31: 1 Bd / 1 Ba | B31: 11 | C31: 2651 | D31: =B31*C31 -> 29161 | E31: =D31*12 -> 349932 | F31: Allocated from published GRM (price / GRM) using LAAA bed weights
A32: Total / weighted avg | B32: =SUM(B30:B31) -> 12 | C32: =IFERROR(D32/B32,"") -> 2584.75 | D32: =SUM(D30:D31) -> 31017 | E32: =SUM(E30:E31) -> 372204
A34: INCOME
B35: OM as presented | C35: LAAA underwritten | F35: Basis / note
A36: Scheduled gross rent | B36: 372257.05 | C36: =E32 -> 372204 | F36: OM column: price / published GRM
A37: Other income (laundry, parking, RUBS) | B37: 0 | C37: 0
A38: Gross scheduled income | B38: =B36+B37 -> 372257.05 | C38: =C36+C37 -> 372204
A39: Vacancy & credit loss | B39: =-B36*0.03 -> -11167.712 | C39: =-C36*Assumptions!$B$3 -> -11166.12 | F39: OM 3.0% (OM figure if extracted, else 3% assumed); LAAA per Assumptions
A40: Effective gross income | B40: =B38+B39 -> 361089.34 | C40: =C38+C39 -> 361037.88
A42: OPERATING EXPENSES
A43: Expense line | B43: OM as presented | C43: LAAA benchmark | D43: LAAA underwritten | E43: Delta vs OM | F43: Basis / note
A44: Property taxes (reassessed at price) | C44: =B22*Assumptions!$B$16 -> 54625 | D44: =C44 -> 54625 | E44: =IF(ISNUMBER(B44),D44-B44,"") | F44: Santa Monica rate x asking price; always reassessed, never MAX
A45: Insurance | C45: =B7*Assumptions!$B$5+B8*Assumptions!$B$6 -> 9680 | D45: =IF(ISNUMBER(B45),MAX(B45,C45),C45) -> 9680 | E45: =IF(ISNUMBER(B45),D45-B45,"") | F45: LAAA benchmark (units x $200) + (SF x $1.00)
A46: Management | C46: =C40*Assumptions!$B$4 -> 18051.894 | D46: =IF(ISNUMBER(B46),MAX(B46,C46),C46) -> 18051.894 | E46: =IF(ISNUMBER(B46),D46-B46,"") | F46: % of LAAA EGI
...
