Workbook

Sheet Assumptions
A1: LAAA UNDERWRITING BENCHMARKS (edit here; every deal tab reads these)
A3: Vacancy & credit loss (% of GSI) | B3: 0.03 | C3: Standard LA practice; vacant units carried at asking rent inside scheduled GSR
A4: Management fee (% of EGI) | B4: 0.05 | C4: Deal-by-deal agent choice; 5% default, MAX(OM, benchmark) used
A5: Insurance: per unit ($) | B5: 200 | C5: LAAA benchmark = (units x $200) + (gross SF x $1.00)
A6: Insurance: per gross SF ($) | B6: 1
A7: Repairs & maintenance per unit, pre-1990 ($/yr) | B7: 1200
A8: Repairs & maintenance per unit, 1990+ ($/yr) | B8: 800
A9: Utilities per unit, LA City ($/yr) | B9: 1500 | C9: Owner-paid water/sewer/trash/common electric+gas (LA Sanitation bundles trash)
A10: Utilities per unit, Santa Monica ($/yr) | B10: 1800 | C10: Separate trash hauler, higher water rates
A11: Utilities per unit, Beverly Hills / WeHo / Culver ($/yr) | B11: 1600
A12: Contract services per unit ($/yr) | B12: 400 | C12: Landscaping, pest, common-area cleaning
A13: Admin / legal / licenses / rent registration per unit ($/yr) | B13: 250 | C13: Includes RSO/rent-board fees, business license, bookkeeping
A14: Replacement reserves per unit ($/yr) | B14: 300
A15: Property tax rate: Los Angeles City | B15: 0.0125 | C15: Ad valorem + direct assessments, reassessed at purchase price
A16: Property tax rate: Santa Monica | B16: 0.0115
A17: Property tax rate: Beverly Hills | B17: 0.0115
A18: Property tax rate: West Hollywood | B18: 0.012
A19: Property tax rate: Culver City | B19: 0.012
A20: Financing: max LTV | B20: 0.6
A21: Financing: min DCR on LAAA NOI | B21: 1.25 | C21: Loan = lesser of LTV loan and DCR-sized loan
A22: Financing: interest rate | B22: 0.0625
A23: Financing: amortization (years) | B23: 30
A24: OM "light" threshold: LAAA total exceeds OM total by more than | B24: 0.05 | C24: Flags OM EXPENSES LIGHT on the deal tab and Master List
A26: Rent-allocation weights when only GRM is published (relative to 1 Bd)
A27: Studio | B27: 0.7
A28: 1 Bd | B28: 1
A29: 2 Bd | B29: 1.35
A30: 3 Bd | B30: 1.75
A32: Estimated in-place rents when NOTHING is published (orange cells on deal tabs)
A33: Coastal (SM / Venice / WeHo / BH): Studio | B33: 1900
A34: Coastal: 1 Bd | B34: 2400
A35: Coastal: 2 Bd | B35: 3200
A36: Coastal: 3 Bd | B36: 4200
A37: West LA / Palms / Culver: Studio | B37: 1750
A38: West LA / Palms / Culver: 1 Bd | B38: 2200
A39: West LA / Palms / Culver: 2 Bd | B39: 2900
A40: West LA / Palms / Culver: 3 Bd | B40: 3800

Sheet 08 519-525 Santa Monica Blvd
A1: 519-525 Santa Monica Blvd
A2: Santa Monica, CA 90401 | Santa Monica
A3: LoopNet listing | B3: Data pulled 9/17/2026 from LoopNet public listing
A4: NOTE: 2012 mixed-use, 43 units (LoopNet) vs 40 in OM extraction
A6: PROPERTY
A7: Units | B7: 43
A8: Gross building SF | B8: 52954
A9: Lot SF | B9: 14810
A10: Lot acres | B10: 0.34
A11: Year built | B11: 2012
A12: Stories | B12: 5
A13: Zoning | B13: SMC3* - Commercial
A14: Occupancy per listing | B14: 95%
A15: APN | B15: 4291-010-012
A16: Assessed value (current) | B16: 34724167
A17: Listing broker(s) | B17: Tony Azzi
A18: Date on market | B18: 3/30/2026
A19: Listing last updated | B19: 8/31/2026
A21: PRICING
A22: Asking price | B22: 32900000
A23: Price per unit | B23: =IFERROR(B22/B7,"") -> 765116.28
A24: Price per gross SF | B24: =IFERROR(B22/B8,"") -> 621.29395
A25: OM / listing cap rate (as published) | B25: 0.0491
A26: OM / listing GRM (as published) | B26: 12.95
A28: UNIT MIX & SCHEDULED RENT
A29: Unit type | B29: # Units | C29: Avg rent / mo | D29: Monthly total | E29: Annual | F29: Rent source
A30: 1 Bd / 1 Ba | B30: 23 | C30: 4607 | D30: =B30*C30 -> 105961 | E30: =D30*12 -> 1271532 | F30: Allocated from published GRM (price / GRM) using LAAA bed weights
A31: 2 Bd / 2 Ba | B31: 17 | C31: 6220 | D31: =B31*C31 -> 105740 | E31: =D31*12 -> 1268880 | F31: Allocated from published GRM (price / GRM) using LAAA bed weights
A32: Total / weighted avg | B32: =SUM(B30:B31) -> 40 | C32: =IFERROR(D32/B32,"") -> 5292.525 | D32: =SUM(D30:D31) -> 211701 | E32: =SUM(E30:E31) -> 2540412
A33: Unit mix rows total 40 vs 43 units in listing facts - verify
A35: INCOME
B36: OM as presented | C36: LAAA underwritten | F36: Basis / note
A37: Scheduled gross rent | B37: 2540540.5 | C37: =E32 -> 2540412 | F37: OM column: price / published GRM
A38: Other income (laundry, parking, RUBS) | B38: 0 | C38: 0
A39: Gross scheduled income | B39: =B37+B38 -> 2540540.5 | C39: =C37+C38 -> 2540412
A40: Vacancy & credit loss | B40: =-B37*0.03 -> -76216.216 | C40: =-C37*Assumptions!$B$3 -> -76212.36 | F40: OM 3.0% (OM figure if extracted, else 3% assumed); LAAA per Assumptions
A41: Effective gross income | B41: =B39+B40 -> 2464324.3 | C41: =C39+C40 -> 2464199.6
A43: OPERATING EXPENSES
A44: Expense line | B44: OM as presented | C44: LAAA benchmark | D44: LAAA underwritten | E44: Delta vs OM | F44: Basis / note
A45: Property taxes (reassessed at price) | C45: =B22*Assumptions!$B$16 -> 378350 | D45: =C45 -> 378350 | E45: =IF(ISNUMBER(B45),D45-B45,"") | F45: Santa Monica rate x asking price; always reassessed, never MAX
...
