Workbook

Sheet Assumptions
A1: LAAA UNDERWRITING BENCHMARKS (edit here; every deal tab reads these)
A3: Vacancy & credit loss (% of GSI) | B3: 0.03 | C3: Standard LA practice; vacant units carried at asking rent inside scheduled GSR
A4: Management fee (% of EGI) | B4: 0.05 | C4: Deal-by-deal agent choice; 5% default, MAX(OM, benchmark) used
A5: Insurance: per unit ($) | B5: 200 | C5: LAAA benchmark = (units x $200) + (gross SF x $1.00)
A6: Insurance: per gross SF ($) | B6: 1
A7: Repairs & maintenance per unit, pre-1990 ($/yr) | B7: 1200
A8: Repairs & maintenance per unit, 1990+ ($/yr) | B8: 800
A9: Utilities per unit, LA City ($/yr) | B9: 1500 | C9: Owner-paid water/sewer/trash/common electric+gas (LA Sanitation bundles trash)
A10: Utilities per unit, Santa Monica ($/yr) | B10: 1800 | C10: Separate trash hauler, higher water rates
A11: Utilities per unit, Beverly Hills / WeHo / Culver ($/yr) | B11: 1600
A12: Contract services per unit ($/yr) | B12: 400 | C12: Landscaping, pest, common-area cleaning
A13: Admin / legal / licenses / rent registration per unit ($/yr) | B13: 250 | C13: Includes RSO/rent-board fees, business license, bookkeeping
A14: Replacement reserves per unit ($/yr) | B14: 300
A15: Property tax rate: Los Angeles City | B15: 0.0125 | C15: Ad valorem + direct assessments, reassessed at purchase price
A16: Property tax rate: Santa Monica | B16: 0.0115
A17: Property tax rate: Beverly Hills | B17: 0.0115
A18: Property tax rate: West Hollywood | B18: 0.012
A19: Property tax rate: Culver City | B19: 0.012
A20: Financing: max LTV | B20: 0.6
A21: Financing: min DCR on LAAA NOI | B21: 1.25 | C21: Loan = lesser of LTV loan and DCR-sized loan
A22: Financing: interest rate | B22: 0.0625
A23: Financing: amortization (years) | B23: 30
A24: OM "light" threshold: LAAA total exceeds OM total by more than | B24: 0.05 | C24: Flags OM EXPENSES LIGHT on the deal tab and Master List
A26: Rent-allocation weights when only GRM is published (relative to 1 Bd)
A27: Studio | B27: 0.7
A28: 1 Bd | B28: 1
A29: 2 Bd | B29: 1.35
A30: 3 Bd | B30: 1.75
A32: Estimated in-place rents when NOTHING is published (orange cells on deal tabs)
A33: Coastal (SM / Venice / WeHo / BH): Studio | B33: 1900
A34: Coastal: 1 Bd | B34: 2400
A35: Coastal: 2 Bd | B35: 3200
A36: Coastal: 3 Bd | B36: 4200
A37: West LA / Palms / Culver: Studio | B37: 1750
A38: West LA / Palms / Culver: 1 Bd | B38: 2200
A39: West LA / Palms / Culver: 2 Bd | B39: 2900
A40: West LA / Palms / Culver: 3 Bd | B40: 3800

Sheet 17 900 N Orange Grove Ave
A1: 900 N Orange Grove Ave
A2: West Hollywood, CA 90046 | West Hollywood
A3: LoopNet listing | B3: Data pulled 9/17/2026 from LoopNet public listing + rent roll and expenses read from the listing broker's OM (Marcus & Millichap, Aug 2026)
A4: NOTE: First sale in 38 years | OM: Unit 21 (1 Bd / 1 Ba) is vacant; OM asking rent $2,300 used as its current rent, per OM convention (OM totals include it in scheduled rent).; Cross-check: sum of 20 unit rents = $33,311/mo ($399,732/yr) vs OM stated $33,310/mo and $399,722/yr GPR; difference is rounding, well within 1%.; Rent roll f | OM: Unit 21 (1 Bd / 1 Ba) is vacant; OM asking rent $2,300 used as its current rent, per OM convention (OM totals include it in scheduled rent).; Cross-check: sum of 20 unit rents = $33,311/mo ($399,732/yr) vs OM stated $33,310/mo and $399,722/yr GPR; difference is rounding, well within 1%.; Rent roll f
A6: PROPERTY
A7: Units | B7: 20
A8: Gross building SF | B8: 14556
A9: Lot SF | B9: 12632
A10: Lot acres | B10: 0.29
A11: Year built | B11: 1957
A12: Stories | B12: 2
A13: Zoning | B13: WDR3C* - Restricted Density Multiple Dwelling
A14: Occupancy per listing
A15: APN | B15: 5530-026-019
A16: Assessed value (current) | B16: 3261097
A17: Listing broker(s) | B17: Jordan Asheghian, Tony Azzi
A18: Date on market | B18: 8/27/2026
A19: Listing last updated | B19: 8/31/2026
A21: PRICING
A22: Asking price | B22: 4150000
A23: Price per unit | B23: =IFERROR(B22/B7,"") -> 207500
A24: Price per gross SF | B24: =IFERROR(B22/B8,"") -> 285.1058
A25: OM / listing cap rate (as published) | B25: 0.0532
A26: OM / listing GRM (as published) | B26: 10.38
A28: UNIT MIX & SCHEDULED RENT
A29: Unit type | B29: # Units | C29: Avg rent / mo | D29: Monthly total | E29: Annual | F29: Rent source
A30: Studio / 1 Ba (~520 SF) [units 5, 6, 16, 17; range $833 to $1,575] | B30: 4 | C30: 1194 | D30: =B30*C30 -> 4776 | E30: =D30*12 -> 57312 | F30: OM rent roll, current in-place rents (OM Aug 2026)
A31: 1 Bd / 1 Ba (~720 SF) [units 1-3, 8-12, 14, 15, 19-21; unit 8 is 900 SF, rest 720 S] | B31: 13 | C31: 1622 | D31: =B31*C31 -> 21086 | E31: =D31*12 -> 253032 | F31: OM rent roll, current in-place rents (OM Aug 2026)
A32: 2 Bd / 1 Ba (~900 SF) [units 7, 18] | B32: 2 | C32: 2545 | D32: =B32*C32 -> 5090 | E32: =D32*12 -> 61080 | F32: OM rent roll, current in-place rents (OM Aug 2026)
A33: 2 Bd / 2 Ba (~900 SF) [unit 4] | B33: 1 | C33: 2363 | D33: =B33*C33 -> 2363 | E33: =D33*12 -> 28356 | F33: OM rent roll, current in-place rents (OM Aug 2026)
A34: Total / weighted avg | B34: =SUM(B30:B33) -> 20 | C34: =IFERROR(D34/B34,"") -> 1665.75 | D34: =SUM(D30:D33) -> 33315 | E34: =SUM(E30:E33) -> 399780
A36: INCOME
B37: OM as presented | C37: LAAA underwritten | F37: Basis / note
A38: Scheduled gross rent | B38: 399722 | C38: =E34 -> 399780 | F38: OM column: OM stated current scheduled rent (OM Aug 2026); LAAA column: OM rent roll by unit type
A39: Other income (laundry, parking, RUBS) | B39: 3000 | C39: 3000
A40: Gross scheduled income | B40: =B38+B39 -> 402722 | C40: =C38+C39 -> 402780
A41: Vacancy & credit loss | B41: =-B38*0.02 -> -7994.44 | C41: =-C38*Assumptions!$B$3 -> -11993.4 | F41: OM 2.0%; LAAA per Assumptions
A42: Effective gross income | B42: =B40+B41 -> 394727.56 | C42: =C40+C41 -> 390786.6
A44: OPERATING EXPENSES
A45: Expense line | B45: OM as presented | C45: LAAA benchmark | D45: LAAA underwritten | E45: Delta vs OM | F45: Basis / note
...
