Workbook

Sheet Assumptions
A1: LAAA UNDERWRITING BENCHMARKS (edit here; every deal tab reads these)
A3: Vacancy & credit loss (% of GSI) | B3: 0.03 | C3: Standard LA practice; vacant units carried at asking rent inside scheduled GSR
A4: Management fee (% of EGI) | B4: 0.05 | C4: Deal-by-deal agent choice; 5% default, MAX(OM, benchmark) used
A5: Insurance: per unit ($) | B5: 200 | C5: LAAA benchmark = (units x $200) + (gross SF x $1.00)
A6: Insurance: per gross SF ($) | B6: 1
A7: Repairs & maintenance per unit, pre-1990 ($/yr) | B7: 1200
A8: Repairs & maintenance per unit, 1990+ ($/yr) | B8: 800
A9: Utilities per unit, LA City ($/yr) | B9: 1500 | C9: Owner-paid water/sewer/trash/common electric+gas (LA Sanitation bundles trash)
A10: Utilities per unit, Santa Monica ($/yr) | B10: 1800 | C10: Separate trash hauler, higher water rates
A11: Utilities per unit, Beverly Hills / WeHo / Culver ($/yr) | B11: 1600
A12: Contract services per unit ($/yr) | B12: 400 | C12: Landscaping, pest, common-area cleaning
A13: Admin / legal / licenses / rent registration per unit ($/yr) | B13: 250 | C13: Includes RSO/rent-board fees, business license, bookkeeping
A14: Replacement reserves per unit ($/yr) | B14: 300
A15: Property tax rate: Los Angeles City | B15: 0.0125 | C15: Ad valorem + direct assessments, reassessed at purchase price
A16: Property tax rate: Santa Monica | B16: 0.0115
A17: Property tax rate: Beverly Hills | B17: 0.0115
A18: Property tax rate: West Hollywood | B18: 0.012
A19: Property tax rate: Culver City | B19: 0.012
A20: Financing: max LTV | B20: 0.6
A21: Financing: min DCR on LAAA NOI | B21: 1.25 | C21: Loan = lesser of LTV loan and DCR-sized loan
A22: Financing: interest rate | B22: 0.0625
A23: Financing: amortization (years) | B23: 30
A24: OM "light" threshold: LAAA total exceeds OM total by more than | B24: 0.05 | C24: Flags OM EXPENSES LIGHT on the deal tab and Master List
A26: Rent-allocation weights when only GRM is published (relative to 1 Bd)
A27: Studio | B27: 0.7
A28: 1 Bd | B28: 1
A29: 2 Bd | B29: 1.35
A30: 3 Bd | B30: 1.75
A32: Estimated in-place rents when NOTHING is published (orange cells on deal tabs)
A33: Coastal (SM / Venice / WeHo / BH): Studio | B33: 1900
A34: Coastal: 1 Bd | B34: 2400
A35: Coastal: 2 Bd | B35: 3200
A36: Coastal: 3 Bd | B36: 4200
A37: West LA / Palms / Culver: Studio | B37: 1750
A38: West LA / Palms / Culver: 1 Bd | B38: 2200
A39: West LA / Palms / Culver: 2 Bd | B39: 2900
A40: West LA / Palms / Culver: 3 Bd | B40: 3800

Sheet 22 222-228 Idaho Ave
A1: 222-228 Idaho Ave
A2: Santa Monica, CA 90403 | Santa Monica
A3: LoopNet listing | B3: Data pulled 9/17/2026 from LoopNet public listing + rent roll and expenses read from the listing broker's OM (Lee & Associates, Berzack, rent roll 9/1/2026)
A4: NOTE: Two parcels 222 & 228 Idaho | OM: Unit-by-unit rents sum to exactly $50,436/mo; OM annual $605,232 = 12 x $50,436 (matches).; Unit 228-3 (1+1) is VACANT; its $2,800 is the OM's asking rent, included in current GSR per OM.; Three units are owner occupied and 'can be delivered vacant' (228-1 $2,750, 228-6 $3,595, 228-10 $2,800); the O | OM: Unit-by-unit rents sum to exactly $50,436/mo; OM annual $605,232 = 12 x $50,436 (matches).; Unit 228-3 (1+1) is VACANT; its $2,800 is the OM's asking rent, included in current GSR per OM.; Three units are owner occupied and 'can be delivered vacant' (228-1 $2,750, 228-6 $3,595, 228-10 $2,800); the O
A6: PROPERTY
A7: Units | B7: 20
A8: Gross building SF | B8: 15006
A9: Lot SF | B9: 14810
A10: Lot acres | B10: 0.34
A11: Year built | B11: 1954
A12: Stories | B12: 2
A13: Zoning | B13: SMR4YY
A14: Occupancy per listing
A15: APN | B15: 4292-023-001
A16: Assessed value (current) | B16: 9991928
A17: Listing broker(s) | B17: Warren Berzack
A18: Date on market | B18: 8/26/2026
A19: Listing last updated | B19: 9/14/2026
A21: PRICING
A22: Asking price | B22: 7795000
A23: Price per unit | B23: =IFERROR(B22/B7,"") -> 389750
A24: Price per gross SF | B24: =IFERROR(B22/B8,"") -> 519.45888
A25: OM / listing cap rate (as published) | B25: 0.0507
A26: OM / listing GRM (as published) | B26: 12.34
A28: UNIT MIX & SCHEDULED RENT
A29: Unit type | B29: # Units | C29: Avg rent / mo | D29: Monthly total | E29: Annual | F29: Rent source
A30: Studio / 1 Ba [OM market/asking rent 2395; OM avg shown 2,298] | B30: 2 | C30: 2298 | D30: =B30*C30 -> 4596 | E30: =D30*12 -> 55152 | F30: OM rent roll, current in-place rents (OM rent roll 9/1/2026)
A31: 1 Bd / 1 Ba [OM market/asking rent 2775; OM avg shown 2,465; includes vac] | B31: 16 | C31: 2465 | D31: =B31*C31 -> 39440 | E31: =D31*12 -> 473280 | F31: OM rent roll, current in-place rents (OM rent roll 9/1/2026)
A32: 2 Bd / 2 Ba [OM market/asking rent 3595; OM avg shown 3,204; 228-6 owner-] | B32: 2 | C32: 3204 | D32: =B32*C32 -> 6408 | E32: =D32*12 -> 76896 | F32: OM rent roll, current in-place rents (OM rent roll 9/1/2026)
A33: Total / weighted avg | B33: =SUM(B30:B32) -> 20 | C33: =IFERROR(D33/B33,"") -> 2522.2 | D33: =SUM(D30:D32) -> 50444 | E33: =SUM(E30:E32) -> 605328
A35: INCOME
B36: OM as presented | C36: LAAA underwritten | F36: Basis / note
A37: Scheduled gross rent | B37: 605232 | C37: =E33 -> 605328 | F37: OM column: OM stated current scheduled rent (OM rent roll 9/1/2026); LAAA column: OM rent roll by unit type
A38: Other income (laundry, parking, RUBS) | B38: 26400 | C38: 26400
A39: Gross scheduled income | B39: =B37+B38 -> 631632 | C39: =C37+C38 -> 631728
A40: Vacancy & credit loss | B40: =-B37*0.03 -> -18156.96 | C40: =-C37*Assumptions!$B$3 -> -18159.84 | F40: OM 3.0%; LAAA per Assumptions
A41: Effective gross income | B41: =B39+B40 -> 613475.04 | C41: =C39+C40 -> 613568.16
A43: OPERATING EXPENSES
A44: Expense line | B44: OM as presented | C44: LAAA benchmark | D44: LAAA underwritten | E44: Delta vs OM | F44: Basis / note
A45: Property taxes (reassessed at price) | B45: 97438 | C45: =B22*Assumptions!$B$16 -> 89642.5 | D45: =C45 -> 89642.5 | E45: =IF(ISNUMBER(B45),D45-B45,"") -> -7795.5 | F45: Santa Monica rate x asking price; always reassessed, never MAX
...
