Workbook

Sheet Assumptions
A1: LAAA UNDERWRITING BENCHMARKS (edit here; every deal tab reads these)
A3: Vacancy & credit loss (% of GSI) | B3: 0.03 | C3: Standard LA practice; vacant units carried at asking rent inside scheduled GSR
A4: Management fee (% of EGI) | B4: 0.05 | C4: Deal-by-deal agent choice; 5% default, MAX(OM, benchmark) used
A5: Insurance: per unit ($) | B5: 200 | C5: LAAA benchmark = (units x $200) + (gross SF x $1.00)
A6: Insurance: per gross SF ($) | B6: 1
A7: Repairs & maintenance per unit, pre-1990 ($/yr) | B7: 1200
A8: Repairs & maintenance per unit, 1990+ ($/yr) | B8: 800
A9: Utilities per unit, LA City ($/yr) | B9: 1500 | C9: Owner-paid water/sewer/trash/common electric+gas (LA Sanitation bundles trash)
A10: Utilities per unit, Santa Monica ($/yr) | B10: 1800 | C10: Separate trash hauler, higher water rates
A11: Utilities per unit, Beverly Hills / WeHo / Culver ($/yr) | B11: 1600
A12: Contract services per unit ($/yr) | B12: 400 | C12: Landscaping, pest, common-area cleaning
A13: Admin / legal / licenses / rent registration per unit ($/yr) | B13: 250 | C13: Includes RSO/rent-board fees, business license, bookkeeping
A14: Replacement reserves per unit ($/yr) | B14: 300
A15: Property tax rate: Los Angeles City | B15: 0.0125 | C15: Ad valorem + direct assessments, reassessed at purchase price
A16: Property tax rate: Santa Monica | B16: 0.0115
A17: Property tax rate: Beverly Hills | B17: 0.0115
A18: Property tax rate: West Hollywood | B18: 0.012
A19: Property tax rate: Culver City | B19: 0.012
A20: Financing: max LTV | B20: 0.6
A21: Financing: min DCR on LAAA NOI | B21: 1.25 | C21: Loan = lesser of LTV loan and DCR-sized loan
A22: Financing: interest rate | B22: 0.0625
A23: Financing: amortization (years) | B23: 30
A24: OM "light" threshold: LAAA total exceeds OM total by more than | B24: 0.05 | C24: Flags OM EXPENSES LIGHT on the deal tab and Master List
A26: Rent-allocation weights when only GRM is published (relative to 1 Bd)
A27: Studio | B27: 0.7
A28: 1 Bd | B28: 1
A29: 2 Bd | B29: 1.35
A30: 3 Bd | B30: 1.75
A32: Estimated in-place rents when NOTHING is published (orange cells on deal tabs)
A33: Coastal (SM / Venice / WeHo / BH): Studio | B33: 1900
A34: Coastal: 1 Bd | B34: 2400
A35: Coastal: 2 Bd | B35: 3200
A36: Coastal: 3 Bd | B36: 4200
A37: West LA / Palms / Culver: Studio | B37: 1750
A38: West LA / Palms / Culver: 1 Bd | B38: 2200
A39: West LA / Palms / Culver: 2 Bd | B39: 2900
A40: West LA / Palms / Culver: 3 Bd | B40: 3800

Sheet 23 1421  1427 Barry Ave
A1: 1421 & 1427 Barry Ave
A2: Los Angeles, CA 90025 | West LA / Sawtelle
A3: LoopNet listing | B3: Data pulled 9/17/2026 from LoopNet public listing
A4: NOTE: CO-LIVING: 18 units / 56 beds, Kaplan master lease through 7/2027. Cap 9.19% published, GSI not published
A6: PROPERTY
A7: Units | B7: 18
A8: Gross building SF | B8: 14924
A9: Lot SF
A10: Lot acres
A11: Year built | B11: 1950
A12: Stories
A13: Zoning
A14: Occupancy per listing
A15: APN
A16: Assessed value (current)
A17: Listing broker(s) | B17: Neema Ahadian, Jeffrey Estrada
A18: Date on market | B18: 2/25/2026
A19: Listing last updated | B19: 8/26/2026
A21: PRICING
A22: Asking price | B22: 9250000
A23: Price per unit | B23: =IFERROR(B22/B7,"") -> 513888.89
A24: Price per gross SF | B24: =IFERROR(B22/B8,"") -> 619.80702
A25: OM / listing cap rate (as published) | B25: 0.0919
A26: OM / listing GRM (as published)
A28: UNIT MIX & SCHEDULED RENT
A29: Unit type | B29: # Units | C29: Avg rent / mo | D29: Monthly total | E29: Annual | F29: Rent source
A30: Co-living beds (56) | B30: 18 | D30: =B30*C30 -> 0 | E30: =D30*12 -> 0 | F30: Income not underwritten: co-living master-lease income not published; OM NOI = price x 9.19% published cap
A31: Total / weighted avg | B31: =SUM(B30:B30) -> 18 | C31: =IFERROR(D31/B31,"") -> 0 | D31: =SUM(D30:D30) -> 0 | E31: =SUM(E30:E30) -> 0
A33: INCOME
B34: OM as presented | C34: LAAA underwritten | F34: Basis / note
A35: Scheduled gross rent | C35: =E31 -> 0 | F35: OM GSR not published
A36: Other income (laundry, parking, RUBS) | B36: 0 | C36: 0
A37: Gross scheduled income | B37: =B35+B36 -> 0 | C37: =C35+C36 -> 0
A38: Vacancy & credit loss | B38: =-B35*0.03 -> 0 | C38: =-C35*Assumptions!$B$3 -> 0 | F38: OM 3.0% (OM figure if extracted, else 3% assumed); LAAA per Assumptions
A39: Effective gross income | B39: =B37+B38 -> 0 | C39: =C37+C38 -> 0
A41: OPERATING EXPENSES
A42: Expense line | B42: OM as presented | C42: LAAA benchmark | D42: LAAA underwritten | E42: Delta vs OM | F42: Basis / note
A43: Property taxes (reassessed at price) | C43: =B22*Assumptions!$B$15 -> 115625 | D43: =C43 -> 115625 | E43: =IF(ISNUMBER(B43),D43-B43,"") | F43: Los Angeles rate x asking price; always reassessed, never MAX
A44: Insurance | C44: =B7*Assumptions!$B$5+B8*Assumptions!$B$6 -> 18524 | D44: =IF(ISNUMBER(B44),MAX(B44,C44),C44) -> 18524 | E44: =IF(ISNUMBER(B44),D44-B44,"") | F44: LAAA benchmark (units x $200) + (SF x $1.00)
A45: Management | C45: =C39*Assumptions!$B$4 -> 0 | D45: =IF(ISNUMBER(B45),MAX(B45,C45),C45) -> 0 | E45: =IF(ISNUMBER(B45),D45-B45,"") | F45: % of LAAA EGI
...
