Workbook

Sheet Assumptions
A1: LAAA UNDERWRITING BENCHMARKS (edit here; every deal tab reads these)
A3: Vacancy & credit loss (% of GSI) | B3: 0.03 | C3: Standard LA practice; vacant units carried at asking rent inside scheduled GSR
A4: Management fee (% of EGI) | B4: 0.05 | C4: Deal-by-deal agent choice; 5% default, MAX(OM, benchmark) used
A5: Insurance: per unit ($) | B5: 200 | C5: LAAA benchmark = (units x $200) + (gross SF x $1.00)
A6: Insurance: per gross SF ($) | B6: 1
A7: Repairs & maintenance per unit, pre-1990 ($/yr) | B7: 1200
A8: Repairs & maintenance per unit, 1990+ ($/yr) | B8: 800
A9: Utilities per unit, LA City ($/yr) | B9: 1500 | C9: Owner-paid water/sewer/trash/common electric+gas (LA Sanitation bundles trash)
A10: Utilities per unit, Santa Monica ($/yr) | B10: 1800 | C10: Separate trash hauler, higher water rates
A11: Utilities per unit, Beverly Hills / WeHo / Culver ($/yr) | B11: 1600
A12: Contract services per unit ($/yr) | B12: 400 | C12: Landscaping, pest, common-area cleaning
A13: Admin / legal / licenses / rent registration per unit ($/yr) | B13: 250 | C13: Includes RSO/rent-board fees, business license, bookkeeping
A14: Replacement reserves per unit ($/yr) | B14: 300
A15: Property tax rate: Los Angeles City | B15: 0.0125 | C15: Ad valorem + direct assessments, reassessed at purchase price
A16: Property tax rate: Santa Monica | B16: 0.0115
A17: Property tax rate: Beverly Hills | B17: 0.0115
A18: Property tax rate: West Hollywood | B18: 0.012
A19: Property tax rate: Culver City | B19: 0.012
A20: Financing: max LTV | B20: 0.6
A21: Financing: min DCR on LAAA NOI | B21: 1.25 | C21: Loan = lesser of LTV loan and DCR-sized loan
A22: Financing: interest rate | B22: 0.0625
A23: Financing: amortization (years) | B23: 30
A24: OM "light" threshold: LAAA total exceeds OM total by more than | B24: 0.05 | C24: Flags OM EXPENSES LIGHT on the deal tab and Master List
A26: Rent-allocation weights when only GRM is published (relative to 1 Bd)
A27: Studio | B27: 0.7
A28: 1 Bd | B28: 1
A29: 2 Bd | B29: 1.35
A30: 3 Bd | B30: 1.75
A32: Estimated in-place rents when NOTHING is published (orange cells on deal tabs)
A33: Coastal (SM / Venice / WeHo / BH): Studio | B33: 1900
A34: Coastal: 1 Bd | B34: 2400
A35: Coastal: 2 Bd | B35: 3200
A36: Coastal: 3 Bd | B36: 4200
A37: West LA / Palms / Culver: Studio | B37: 1750
A38: West LA / Palms / Culver: 1 Bd | B38: 2200
A39: West LA / Palms / Culver: 2 Bd | B39: 2900
A40: West LA / Palms / Culver: 3 Bd | B40: 3800

Sheet 24 8468 Fountain Ave
A1: 8468 Fountain Ave
A2: West Hollywood, CA 90069 | West Hollywood
A3: LoopNet listing | B3: Data pulled 9/17/2026 from LoopNet public listing
A6: PROPERTY
A7: Units | B7: 13
A8: Gross building SF | B8: 13131
A9: Lot SF | B9: 11761
A10: Lot acres | B10: 0.27
A11: Year built | B11: 1939
A12: Stories | B12: 2
A13: Zoning | B13: R4, West Hollywood - Restricted Density Multiple Dwelling
A14: Occupancy per listing | B14: 97%
A15: APN | B15: 5555-004-013
A16: Assessed value (current) | B16: 2254000
A17: Listing broker(s) | B17: Michael Kamara
A18: Date on market | B18: 7/16/2026
A19: Listing last updated | B19: 9/14/2026
A21: PRICING
A22: Asking price | B22: 5995000
A23: Price per unit | B23: =IFERROR(B22/B7,"") -> 461153.85
A24: Price per gross SF | B24: =IFERROR(B22/B8,"") -> 456.55319
A25: OM / listing cap rate (as published) | B25: 0.0488
A26: OM / listing GRM (as published) | B26: 15.13
A28: UNIT MIX & SCHEDULED RENT
A29: Unit type | B29: # Units | C29: Avg rent / mo | D29: Monthly total | E29: Annual | F29: Rent source
A30: Studio | B30: 1 | C30: 1681 | D30: =B30*C30 -> 1681 | E30: =D30*12 -> 20172 | F30: Allocated from published GRM (price / GRM) using LAAA bed weights
A31: 1 Bd / 1 Ba | B31: 9 | C31: 2401 | D31: =B31*C31 -> 21609 | E31: =D31*12 -> 259308 | F31: Allocated from published GRM (price / GRM) using LAAA bed weights
A32: 2 Bd / 2 Ba | B32: 2 | C32: 3242 | D32: =B32*C32 -> 6484 | E32: =D32*12 -> 77808 | F32: Allocated from published GRM (price / GRM) using LAAA bed weights
A33: 2 Bd / 2.5 Ba | B33: 1 | C33: 3242 | D33: =B33*C33 -> 3242 | E33: =D33*12 -> 38904 | F33: Allocated from published GRM (price / GRM) using LAAA bed weights
A34: Total / weighted avg | B34: =SUM(B30:B33) -> 13 | C34: =IFERROR(D34/B34,"") -> 2539.6923 | D34: =SUM(D30:D33) -> 33016 | E34: =SUM(E30:E33) -> 396192
A36: INCOME
B37: OM as presented | C37: LAAA underwritten | F37: Basis / note
A38: Scheduled gross rent | B38: 396232.65 | C38: =E34 -> 396192 | F38: OM column: price / published GRM
A39: Other income (laundry, parking, RUBS) | B39: 0 | C39: 0
A40: Gross scheduled income | B40: =B38+B39 -> 396232.65 | C40: =C38+C39 -> 396192
A41: Vacancy & credit loss | B41: =-B38*0.03 -> -11886.98 | C41: =-C38*Assumptions!$B$3 -> -11885.76 | F41: OM 3.0% (OM figure if extracted, else 3% assumed); LAAA per Assumptions
A42: Effective gross income | B42: =B40+B41 -> 384345.67 | C42: =C40+C41 -> 384306.24
A44: OPERATING EXPENSES
A45: Expense line | B45: OM as presented | C45: LAAA benchmark | D45: LAAA underwritten | E45: Delta vs OM | F45: Basis / note
A46: Property taxes (reassessed at price) | C46: =B22*Assumptions!$B$18 -> 71940 | D46: =C46 -> 71940 | E46: =IF(ISNUMBER(B46),D46-B46,"") | F46: West Hollywood rate x asking price; always reassessed, never MAX
...
