Workbook

Sheet Assumptions
A1: LAAA UNDERWRITING BENCHMARKS (edit here; every deal tab reads these)
A3: Vacancy & credit loss (% of GSI) | B3: 0.03 | C3: Standard LA practice; vacant units carried at asking rent inside scheduled GSR
A4: Management fee (% of EGI) | B4: 0.05 | C4: Deal-by-deal agent choice; 5% default, MAX(OM, benchmark) used
A5: Insurance: per unit ($) | B5: 200 | C5: LAAA benchmark = (units x $200) + (gross SF x $1.00)
A6: Insurance: per gross SF ($) | B6: 1
A7: Repairs & maintenance per unit, pre-1990 ($/yr) | B7: 1200
A8: Repairs & maintenance per unit, 1990+ ($/yr) | B8: 800
A9: Utilities per unit, LA City ($/yr) | B9: 1500 | C9: Owner-paid water/sewer/trash/common electric+gas (LA Sanitation bundles trash)
A10: Utilities per unit, Santa Monica ($/yr) | B10: 1800 | C10: Separate trash hauler, higher water rates
A11: Utilities per unit, Beverly Hills / WeHo / Culver ($/yr) | B11: 1600
A12: Contract services per unit ($/yr) | B12: 400 | C12: Landscaping, pest, common-area cleaning
A13: Admin / legal / licenses / rent registration per unit ($/yr) | B13: 250 | C13: Includes RSO/rent-board fees, business license, bookkeeping
A14: Replacement reserves per unit ($/yr) | B14: 300
A15: Property tax rate: Los Angeles City | B15: 0.0125 | C15: Ad valorem + direct assessments, reassessed at purchase price
A16: Property tax rate: Santa Monica | B16: 0.0115
A17: Property tax rate: Beverly Hills | B17: 0.0115
A18: Property tax rate: West Hollywood | B18: 0.012
A19: Property tax rate: Culver City | B19: 0.012
A20: Financing: max LTV | B20: 0.6
A21: Financing: min DCR on LAAA NOI | B21: 1.25 | C21: Loan = lesser of LTV loan and DCR-sized loan
A22: Financing: interest rate | B22: 0.0625
A23: Financing: amortization (years) | B23: 30
A24: OM "light" threshold: LAAA total exceeds OM total by more than | B24: 0.05 | C24: Flags OM EXPENSES LIGHT on the deal tab and Master List
A26: Rent-allocation weights when only GRM is published (relative to 1 Bd)
A27: Studio | B27: 0.7
A28: 1 Bd | B28: 1
A29: 2 Bd | B29: 1.35
A30: 3 Bd | B30: 1.75
A32: Estimated in-place rents when NOTHING is published (orange cells on deal tabs)
A33: Coastal (SM / Venice / WeHo / BH): Studio | B33: 1900
A34: Coastal: 1 Bd | B34: 2400
A35: Coastal: 2 Bd | B35: 3200
A36: Coastal: 3 Bd | B36: 4200
A37: West LA / Palms / Culver: Studio | B37: 1750
A38: West LA / Palms / Culver: 1 Bd | B38: 2200
A39: West LA / Palms / Culver: 2 Bd | B39: 2900
A40: West LA / Palms / Culver: 3 Bd | B40: 3800

Sheet 31 3602 Keystone Ave
A1: 3602 Keystone Ave
A2: Los Angeles, CA 90034 | Palms
A3: LoopNet listing | B3: Data pulled 9/17/2026 from LoopNet public listing
A4: NOTE: 80% occupied
A6: PROPERTY
A7: Units | B7: 10
A8: Gross building SF | B8: 7032
A9: Lot SF | B9: 7405
A10: Lot acres | B10: 0.17
A11: Year built | B11: 1967
A12: Stories | B12: 2
A13: Zoning | B13: LAR3 - Restricted Density Multiple Dwelling
A14: Occupancy per listing | B14: 80%
A15: APN | B15: 4314-009-036
A16: Assessed value (current) | B16: 2610677
A17: Listing broker(s) | B17: Peter James, Will James
A18: Date on market | B18: 8/13/2026
A19: Listing last updated | B19: 9/8/2026
A21: PRICING
A22: Asking price | B22: 2675000
A23: Price per unit | B23: =IFERROR(B22/B7,"") -> 267500
A24: Price per gross SF | B24: =IFERROR(B22/B8,"") -> 380.40387
A25: OM / listing cap rate (as published) | B25: 0.0561
A26: OM / listing GRM (as published) | B26: 11.19
A28: UNIT MIX & SCHEDULED RENT
A29: Unit type | B29: # Units | C29: Avg rent / mo | D29: Monthly total | E29: Annual | F29: Rent source
A30: 1 Bd / 1 Ba | B30: 7 | C30: 2250 | D30: =B30*C30 -> 15750 | E30: =D30*12 -> 189000 | F30: LoopNet published avg rent by unit type
A31: 2 Bd / 1.5 Ba | B31: 2 | C31: 2750 | D31: =B31*C31 -> 5500 | E31: =D31*12 -> 66000 | F31: LoopNet published avg rent by unit type
A32: Studio | B32: 1 | C32: 1650 | D32: =B32*C32 -> 1650 | E32: =D32*12 -> 19800 | F32: LoopNet published avg rent by unit type
A33: Total / weighted avg | B33: =SUM(B30:B32) -> 10 | C33: =IFERROR(D33/B33,"") -> 2290 | D33: =SUM(D30:D32) -> 22900 | E33: =SUM(E30:E32) -> 274800
A35: INCOME
B36: OM as presented | C36: LAAA underwritten | F36: Basis / note
A37: Scheduled gross rent | B37: 239052.73 | C37: =E33 -> 274800 | F37: OM column: price / published GRM
A38: Other income (laundry, parking, RUBS) | B38: 0 | C38: 0
A39: Gross scheduled income | B39: =B37+B38 -> 239052.73 | C39: =C37+C38 -> 274800
A40: Vacancy & credit loss | B40: =-B37*0.03 -> -7171.5818 | C40: =-C37*Assumptions!$B$3 -> -8244 | F40: OM 3.0% (OM figure if extracted, else 3% assumed); LAAA per Assumptions
A41: Effective gross income | B41: =B39+B40 -> 231881.14 | C41: =C39+C40 -> 266556
A43: OPERATING EXPENSES
A44: Expense line | B44: OM as presented | C44: LAAA benchmark | D44: LAAA underwritten | E44: Delta vs OM | F44: Basis / note
A45: Property taxes (reassessed at price) | C45: =B22*Assumptions!$B$15 -> 33437.5 | D45: =C45 -> 33437.5 | E45: =IF(ISNUMBER(B45),D45-B45,"") | F45: Los Angeles rate x asking price; always reassessed, never MAX
...
