Workbook

Sheet Assumptions
A1: LAAA UNDERWRITING BENCHMARKS (edit here; every deal tab reads these)
A3: Vacancy & credit loss (% of GSI) | B3: 0.03 | C3: Standard LA practice; vacant units carried at asking rent inside scheduled GSR
A4: Management fee (% of EGI) | B4: 0.05 | C4: Deal-by-deal agent choice; 5% default, MAX(OM, benchmark) used
A5: Insurance: per unit ($) | B5: 200 | C5: LAAA benchmark = (units x $200) + (gross SF x $1.00)
A6: Insurance: per gross SF ($) | B6: 1
A7: Repairs & maintenance per unit, pre-1990 ($/yr) | B7: 1200
A8: Repairs & maintenance per unit, 1990+ ($/yr) | B8: 800
A9: Utilities per unit, LA City ($/yr) | B9: 1500 | C9: Owner-paid water/sewer/trash/common electric+gas (LA Sanitation bundles trash)
A10: Utilities per unit, Santa Monica ($/yr) | B10: 1800 | C10: Separate trash hauler, higher water rates
A11: Utilities per unit, Beverly Hills / WeHo / Culver ($/yr) | B11: 1600
A12: Contract services per unit ($/yr) | B12: 400 | C12: Landscaping, pest, common-area cleaning
A13: Admin / legal / licenses / rent registration per unit ($/yr) | B13: 250 | C13: Includes RSO/rent-board fees, business license, bookkeeping
A14: Replacement reserves per unit ($/yr) | B14: 300
A15: Property tax rate: Los Angeles City | B15: 0.0125 | C15: Ad valorem + direct assessments, reassessed at purchase price
A16: Property tax rate: Santa Monica | B16: 0.0115
A17: Property tax rate: Beverly Hills | B17: 0.0115
A18: Property tax rate: West Hollywood | B18: 0.012
A19: Property tax rate: Culver City | B19: 0.012
A20: Financing: max LTV | B20: 0.6
A21: Financing: min DCR on LAAA NOI | B21: 1.25 | C21: Loan = lesser of LTV loan and DCR-sized loan
A22: Financing: interest rate | B22: 0.0625
A23: Financing: amortization (years) | B23: 30
A24: OM "light" threshold: LAAA total exceeds OM total by more than | B24: 0.05 | C24: Flags OM EXPENSES LIGHT on the deal tab and Master List
A26: Rent-allocation weights when only GRM is published (relative to 1 Bd)
A27: Studio | B27: 0.7
A28: 1 Bd | B28: 1
A29: 2 Bd | B29: 1.35
A30: 3 Bd | B30: 1.75
A32: Estimated in-place rents when NOTHING is published (orange cells on deal tabs)
A33: Coastal (SM / Venice / WeHo / BH): Studio | B33: 1900
A34: Coastal: 1 Bd | B34: 2400
A35: Coastal: 2 Bd | B35: 3200
A36: Coastal: 3 Bd | B36: 4200
A37: West LA / Palms / Culver: Studio | B37: 1750
A38: West LA / Palms / Culver: 1 Bd | B38: 2200
A39: West LA / Palms / Culver: 2 Bd | B39: 2900
A40: West LA / Palms / Culver: 3 Bd | B40: 3800

Sheet 39 7550 Fountain Ave
A1: 7550 Fountain Ave
A2: West Hollywood, CA 90046 | West Hollywood
A3: LoopNet listing | B3: Data pulled 9/17/2026 from LoopNet public listing
A4: NOTE: No cap/GRM published; rents estimated
A6: PROPERTY
A7: Units | B7: 10
A8: Gross building SF | B8: 9444
A9: Lot SF | B9: 6970
A10: Lot acres | B10: 0.16
A11: Year built | B11: 1958
A12: Stories | B12: 2
A13: Zoning | B13: WDR2* - Two-Family Dwellings
A14: Occupancy per listing | B14: 100%
A15: APN | B15: 5530-005-002
A16: Assessed value (current) | B16: 3580514
A17: Listing broker(s) | B17: Yar Meshkaty
A18: Date on market | B18: 2/18/2026
A19: Listing last updated | B19: 9/11/2026
A21: PRICING
A22: Asking price | B22: 3795000
A23: Price per unit | B23: =IFERROR(B22/B7,"") -> 379500
A24: Price per gross SF | B24: =IFERROR(B22/B8,"") -> 401.84244
A25: OM / listing cap rate (as published)
A26: OM / listing GRM (as published)
A28: UNIT MIX & SCHEDULED RENT
A29: Unit type | B29: # Units | C29: Avg rent / mo | D29: Monthly total | E29: Annual | F29: Rent source
A30: 1 Bd / 1 Ba | B30: 6 | C30: 2400 | D30: =B30*C30 -> 14400 | E30: =D30*12 -> 172800 | F30: ESTIMATED (no rents, GRM or cap published) - verify with OM
A31: 2 Bd / 2 Ba | B31: 4 | C31: 3200 | D31: =B31*C31 -> 12800 | E31: =D31*12 -> 153600 | F31: ESTIMATED (no rents, GRM or cap published) - verify with OM
A32: Total / weighted avg | B32: =SUM(B30:B31) -> 10 | C32: =IFERROR(D32/B32,"") -> 2720 | D32: =SUM(D30:D31) -> 27200 | E32: =SUM(E30:E31) -> 326400
A34: INCOME
B35: OM as presented | C35: LAAA underwritten | F35: Basis / note
A36: Scheduled gross rent | C36: =E32 -> 326400 | F36: OM GSR not published
A37: Other income (laundry, parking, RUBS) | B37: 0 | C37: 0
A38: Gross scheduled income | B38: =B36+B37 -> 0 | C38: =C36+C37 -> 326400
A39: Vacancy & credit loss | B39: =-B36*0.03 -> 0 | C39: =-C36*Assumptions!$B$3 -> -9792 | F39: OM 3.0% (OM figure if extracted, else 3% assumed); LAAA per Assumptions
A40: Effective gross income | B40: =B38+B39 -> 0 | C40: =C38+C39 -> 316608
A42: OPERATING EXPENSES
A43: Expense line | B43: OM as presented | C43: LAAA benchmark | D43: LAAA underwritten | E43: Delta vs OM | F43: Basis / note
A44: Property taxes (reassessed at price) | C44: =B22*Assumptions!$B$18 -> 45540 | D44: =C44 -> 45540 | E44: =IF(ISNUMBER(B44),D44-B44,"") | F44: West Hollywood rate x asking price; always reassessed, never MAX
A45: Insurance | C45: =B7*Assumptions!$B$5+B8*Assumptions!$B$6 -> 11444 | D45: =IF(ISNUMBER(B45),MAX(B45,C45),C45) -> 11444 | E45: =IF(ISNUMBER(B45),D45-B45,"") | F45: LAAA benchmark (units x $200) + (SF x $1.00)
...
