Workbook

Sheet Assumptions
A1: LAAA UNDERWRITING BENCHMARKS (edit here; every deal tab reads these)
A3: Vacancy & credit loss (% of GSI) | B3: 0.03 | C3: Standard LA practice; vacant units carried at asking rent inside scheduled GSR
A4: Management fee (% of EGI) | B4: 0.05 | C4: Deal-by-deal agent choice; 5% default, MAX(OM, benchmark) used
A5: Insurance: per unit ($) | B5: 200 | C5: LAAA benchmark = (units x $200) + (gross SF x $1.00)
A6: Insurance: per gross SF ($) | B6: 1
A7: Repairs & maintenance per unit, pre-1990 ($/yr) | B7: 1200
A8: Repairs & maintenance per unit, 1990+ ($/yr) | B8: 800
A9: Utilities per unit, LA City ($/yr) | B9: 1500 | C9: Owner-paid water/sewer/trash/common electric+gas (LA Sanitation bundles trash)
A10: Utilities per unit, Santa Monica ($/yr) | B10: 1800 | C10: Separate trash hauler, higher water rates
A11: Utilities per unit, Beverly Hills / WeHo / Culver ($/yr) | B11: 1600
A12: Contract services per unit ($/yr) | B12: 400 | C12: Landscaping, pest, common-area cleaning
A13: Admin / legal / licenses / rent registration per unit ($/yr) | B13: 250 | C13: Includes RSO/rent-board fees, business license, bookkeeping
A14: Replacement reserves per unit ($/yr) | B14: 300
A15: Property tax rate: Los Angeles City | B15: 0.0125 | C15: Ad valorem + direct assessments, reassessed at purchase price
A16: Property tax rate: Santa Monica | B16: 0.0115
A17: Property tax rate: Beverly Hills | B17: 0.0115
A18: Property tax rate: West Hollywood | B18: 0.012
A19: Property tax rate: Culver City | B19: 0.012
A20: Financing: max LTV | B20: 0.6
A21: Financing: min DCR on LAAA NOI | B21: 1.25 | C21: Loan = lesser of LTV loan and DCR-sized loan
A22: Financing: interest rate | B22: 0.0625
A23: Financing: amortization (years) | B23: 30
A24: OM "light" threshold: LAAA total exceeds OM total by more than | B24: 0.05 | C24: Flags OM EXPENSES LIGHT on the deal tab and Master List
A26: Rent-allocation weights when only GRM is published (relative to 1 Bd)
A27: Studio | B27: 0.7
A28: 1 Bd | B28: 1
A29: 2 Bd | B29: 1.35
A30: 3 Bd | B30: 1.75
A32: Estimated in-place rents when NOTHING is published (orange cells on deal tabs)
A33: Coastal (SM / Venice / WeHo / BH): Studio | B33: 1900
A34: Coastal: 1 Bd | B34: 2400
A35: Coastal: 2 Bd | B35: 3200
A36: Coastal: 3 Bd | B36: 4200
A37: West LA / Palms / Culver: Studio | B37: 1750
A38: West LA / Palms / Culver: 1 Bd | B38: 2200
A39: West LA / Palms / Culver: 2 Bd | B39: 2900
A40: West LA / Palms / Culver: 3 Bd | B40: 3800

Sheet 46 1269 Havenhurst Dr
A1: 1269 Havenhurst Dr (Casa Julieta)
A2: West Hollywood, CA 90046 | West Hollywood
A3: LoopNet listing | B3: Data pulled 9/17/2026 from LoopNet public listing
A6: PROPERTY
A7: Units | B7: 10
A8: Gross building SF | B8: 10171
A9: Lot SF | B9: 15246
A10: Lot acres | B10: 0.35
A11: Year built | B11: 1939
A12: Stories | B12: 2
A13: Zoning | B13: WDR4 - R4 zoning district provides for the development of a wide range of high-density multi-family housing, including apartments and condominiums.
A14: Occupancy per listing | B14: 100%
A15: APN | B15: 5554-016-033
A16: Assessed value (current) | B16: 597131
A17: Listing broker(s) | B17: Mason Canter
A18: Date on market | B18: 7/15/2026
A19: Listing last updated | B19: 7/15/2026
A21: PRICING
A22: Asking price | B22: 4995000
A23: Price per unit | B23: =IFERROR(B22/B7,"") -> 499500
A24: Price per gross SF | B24: =IFERROR(B22/B8,"") -> 491.10215
A25: OM / listing cap rate (as published) | B25: 0.038
A26: OM / listing GRM (as published) | B26: 16.27
A28: UNIT MIX & SCHEDULED RENT
A29: Unit type | B29: # Units | C29: Avg rent / mo | D29: Monthly total | E29: Annual | F29: Rent source
A30: 2 Bd / 1 Ba | B30: 4 | C30: 2736 | D30: =B30*C30 -> 10944 | E30: =D30*12 -> 131328 | F30: LoopNet published avg rent by unit type
A31: 1 Bd / 1 Ba | B31: 6 | C31: 2424 | D31: =B31*C31 -> 14544 | E31: =D31*12 -> 174528 | F31: LoopNet published avg rent by unit type
A32: Total / weighted avg | B32: =SUM(B30:B31) -> 10 | C32: =IFERROR(D32/B32,"") -> 2548.8 | D32: =SUM(D30:D31) -> 25488 | E32: =SUM(E30:E31) -> 305856
A34: INCOME
B35: OM as presented | C35: LAAA underwritten | F35: Basis / note
A36: Scheduled gross rent | B36: 307006.76 | C36: =E32 -> 305856 | F36: OM column: price / published GRM
A37: Other income (laundry, parking, RUBS) | B37: 0 | C37: 0
A38: Gross scheduled income | B38: =B36+B37 -> 307006.76 | C38: =C36+C37 -> 305856
A39: Vacancy & credit loss | B39: =-B36*0.03 -> -9210.2028 | C39: =-C36*Assumptions!$B$3 -> -9175.68 | F39: OM 3.0% (OM figure if extracted, else 3% assumed); LAAA per Assumptions
A40: Effective gross income | B40: =B38+B39 -> 297796.56 | C40: =C38+C39 -> 296680.32
A42: OPERATING EXPENSES
A43: Expense line | B43: OM as presented | C43: LAAA benchmark | D43: LAAA underwritten | E43: Delta vs OM | F43: Basis / note
A44: Property taxes (reassessed at price) | C44: =B22*Assumptions!$B$18 -> 59940 | D44: =C44 -> 59940 | E44: =IF(ISNUMBER(B44),D44-B44,"") | F44: West Hollywood rate x asking price; always reassessed, never MAX
A45: Insurance | C45: =B7*Assumptions!$B$5+B8*Assumptions!$B$6 -> 12171 | D45: =IF(ISNUMBER(B45),MAX(B45,C45),C45) -> 12171 | E45: =IF(ISNUMBER(B45),D45-B45,"") | F45: LAAA benchmark (units x $200) + (SF x $1.00)
A46: Management | C46: =C40*Assumptions!$B$4 -> 14834.016 | D46: =IF(ISNUMBER(B46),MAX(B46,C46),C46) -> 14834.016 | E46: =IF(ISNUMBER(B46),D46-B46,"") | F46: % of LAAA EGI
...
